Workbook

Sheet Assumptions
C3: Assumptions for Karnataka
B4: 1 | C4: IT Exports - Karnataka contributes to 38% of India's IT Exports
B5: 2 | C5: IT Domestic - Karnataka contributes to 30% of India's share
B6: 3 | C6: ESDM - Karnataka share is considered at 20%
B7: 4 | C7: Startups - Karnataka's share is 40%
C9: Assumptions for Beyond Bengaluru (Figures assumed based on Beyond Bengaluru Report)
B10: 1 | C10: IT Exports - Beyond Bengaluru contribution
B11: 2 | C11: IT Domestic - Beyond Bengaluru contribution
B12: 3 | C12: ESDM - Beyond Bengaluru contributes 5% of Karnataka's share
B13: 4 | C13: Startups - Beyond Bengaluru contributes 25% of Karnataka's share
C16: Revenue growth assumptions made for the calculation (Revenue) | H16: Assumptions for employment based on ratio of revenue growth
E18: Till the year 2025 | F18: From the year 2025-2030 | H18: Share of Beyond Bengaluru:
C19: IT Exports (India and Karnataka) | E19: 0.12 | F19: 0.1 | H19: IT Exports and IT Domestic
C20: IT Domestic (India and Karnataka) | E20: 0.15 | F20: 0.12 | H20: ESDM
C21: Startups (India and Karnataka) | E21: 0.3 | F21: 0.2 | H21: Startups
C22: ESDM (India and Karnataka) | D22: As per ICEA estimates (USD 300 Bn by 2025) (Have excluded consumer electronics)
E25: CAGR for Karnataka (In %) | F25: CAGR for India (In %)
C26: Other sub-sectors of digital economy: | D26: Share of Karnataka | E26: Till the year 2025 | F26: Till the year 2025 | G26: 2025-26 to 2030-31 for Karnataka | H26: 2025-26 to 2030-31 for India
C27: Digital Communication Services | D27: 0.065 | E27: 23.59 | F27: 17.72 | G27: 0.15 | H27: 0.1
C28: Government e-Market place | D28: 0.1 | E28: 18.8 | F28: 17.76 | G28: 0.15 | H28: 0.1
C29: Direct Benefit Transfer | D29: 0.15 | E29: 24.5 | F29: 21 | G29: 0.15 | H29: 0.1
C30: Tech-enabled healthcare | D30: 0.08 | E30: 20 | F30: 49.5 | G30: 0.15 | H30: 0.1
C31: Customizable education platform for students | D31: 0.05 | E31: 40 | F31: 36.78 | G31: 0.15 | H31: 0.1
C32: Digitally enabled power distribution | D32: 0.08 | E32: 96 | F32: 82 | G32: 0.15 | H32: 0.1
C33: Smart grids with distributed generation | D33: 0.08 | E33: 40 | F33: 40 | G33: 0.15 | H33: 0.1
C34: Digital payments | D34: 0.1 | E34: 45 | F34: 62.66 | G34: 0.15 | H34: 0.1
C35: Flow based lending and advanced credit (MSME's) | D35: 0.06 | E35: 70 | F35: 80 | G35: 0.15 | H35: 0.1
C36: Digital Farmer financing and insurance payouts | D36: 0.13 | E36: 75 | F36: 88 | G36: 0.15 | H36: 0.1
C37: Precision agriculture | D37: 0.09 | E37: 85 | F37: 118 | G37: 0.15 | H37: 0.1
C38: Universal agricultural marketplace | D38: 0.06 | E38: 110 | F38: 118 | G38: 0.15 | H38: 0.1
... C43: Business digitization and IoT based analytics | D43: 0.09 | E43: 200 | F43: 227 | G43: 0.15 | H43: 0.1
C44: ** For Growth in Beyond Bengaluru assumed at 5% for other sub sectors of digital economy

Sheet Estimation of Revenue
C1: Digital Economy Sector - India and Karnataka
C2: 2021-22 Data | P2: =O10*25% -> 1.3 | AA2: =0.08 -> 0.08
C3: Total Revenue India level | M3: Projected estimation of values (2022-2030) | O3: =N10*40% -> 5.2 | P3: =N9*20% -> 24.314883 | Q3: >> For ESDM | AA3: 0.2 | AB3: =AA3-AA2 -> 0.12 | AC3: =AB3/AA2*100 -> 150
C4: In USD Bn $ | AQ4: Karnataka value for startups
C5: Total Revenue | D5: India | E5: Karnataka | G5: Beyond Bengaluru | I5: Bangalore | M5: (In Bn $ USD) | N5: 2022-23 | Q5: 2023-24 | T5: 2024-25 | W5: 2025-26 | Z5: 2026-27 | AC5: 2027-28 | AF5: 2028-29 | AI5: 2029-30 | AL5: 2030-31 | AQ5: 2030-31 | AR5: 2031-32 | AS5: 2032-33 | AT5: FY 33-34 | AU5: FY 34-35 | AV5: FY 35-36 | AW5: FY 36-37 | AX5: FY 37-38 | AY5: FY 38-39 | AZ5: FY 39-40 | BA5: FY 40-41 | BB5: FY 41-42 | BC5: FY 42-43 | BD5: FY 43-44 | BE5: FY 44-45 | BF5: FY 45-46 | BG5: FY 46-47
M6: Revenue | N6: India | O6: Karnataka | P6: Beyond Bengaluru | Q6: India | R6: Karnataka | S6: Beyond Bengaluru | T6: India | U6: Karnataka | V6: Beyond Bengaluru | W6: India | X6: Karnataka | Y6: Beyond Bengaluru | Z6: India | AA6: Karnataka | AB6: Beyond Bengaluru | AC6: India | AD6: Karnataka | AE6: Beyond Bengaluru | AF6: India | AG6: Karnataka | AH6: Beyond Bengaluru | AI6: India | AJ6: Karnataka | AK6: Beyond Bengaluru | AL6: India | AM6: Karnataka | AN6: Beyond Bengaluru
C7: IT Exports | D7: 178 | E7: =D7*38% -> 67.64 | G7: ='Beyond Bengaluru Workings'!D9 -> 2 | I7: =E7-G7 -> 65.64 | M7: IT Exports | N7: =D7+12%*D7 -> 199.36 | O7: =E7+12%*E7 -> 75.7568 | P7: ='Beyond Bengaluru Workings'!E9 -> 2.5 | Q7: =N7+12%*N7 -> 223.2832 | R7: =O7+12%*O7 -> 84.847616 | S7: ='Beyond Bengaluru Workings'!F9 -> 3.125 | T7: =Q7+12%*Q7 -> 250.07718 | U7: =R7+12%*R7 -> 95.02933 | V7: ='Beyond Bengaluru Workings'!G9 -> 3.90625 | W7: =T7+12%*T7 -> 280.08645 | X7: =U7+12%*U7 -> 106.43285 | Y7: ='Beyond Bengaluru Workings'!H9 -> 4.8828125 | Z7: =W7+10%*W7 -> 308.09509 | AA7: =X7+10%*X7 -> 117.07613 | AB7: ='Beyond Bengaluru Workings'!I9 -> 5.7714844 | AC7: =Z7+10%*Z7 -> 338.9046 | AD7: =AA7+25%*AA7 -> 146.34517 | AE7: ='Beyond Bengaluru Workings'!J9 -> 6.8218945 | AF7: =AC7+10%*AC7 -> 372.79506 | AG7: =AD7+25%*AD7 -> 182.93146 | AH7: ='Beyond Bengaluru Workings'!K9 -> 8.0634793 | AI7: =AF7+10%*AF7 -> 410.07457 | AJ7: =AG7+25%*AG7 -> 228.66433 | AK7: ='Beyond Bengaluru Workings'!L9 -> 9.5310326 | AL7: =AI7+10%*AI7 -> 451.08202 | AM7: =AJ7+10%*AJ7 -> 251.53076 | AN7: =AK7+15%*AK7 -> 10.960687 | AP7: IT Exports | AQ7: 240.226 | AR7: =AQ7+15%*AQ7 -> 276.25991 | AS7: =AR7+15%*AR7 -> 317.69889 | AT7: =AS7+15%*AS7 -> 365.35372 | AU7: =AT7+15%*AT7 -> 420.15678 | AV7: =AU7+15%*AU7 -> 483.1803 | AW7: =AV7+15%*AV7 -> 555.65735 | AX7: =AW7+15%*AW7 -> 639.00595 | AY7: =AX7+15%*AX7 -> 734.85684 | ... BG7: =BF7+15%*BF7 -> 2247.9439
C8: IT Domestic | D8: 49 | E8: =D8*30% -> 14.7 | I8: =E8-G8 -> 14.7 | M8: IT Domestic | N8: =D8+15%*D8 -> 56.35 | O8: =E8+15%*E8 -> 16.905 | P8: =G8+20%*G8 -> 0 | Q8: =N8+15%*N8 -> 64.8025 | R8: =O8+15%*O8 -> 19.44075 | S8: =P8+20%*P8 -> 0 | T8: =Q8+15%*Q8 -> 74.522875 | U8: =R8+15%*R8 -> 22.356862 | V8: =S8+20%*S8 -> 0 | W8: =T8+15%*T8 -> 85.701306 | X8: =U8+15%*U8 -> 25.710392 | Y8: =V8+20%*V8 -> 0 | Z8: =W8+12%*W8 -> 95.985463 | AA8: =X8+12%*X8 -> 28.795639 | AB8: =Y8+15%*Y8 -> 0 | AC8: =Z8+12%*Z8 -> 107.50372 | AD8: =AA8+25%*AA8 -> 35.994549 | AE8: =AB8+15%*AB8 -> 0 | AF8: =AC8+12%*AC8 -> 120.40416 | AG8: =AD8+25%*AD8 -> 44.993186 | AH8: =AE8+15%*AE8 -> 0 | AI8: =AF8+12%*AF8 -> 134.85266 | AJ8: =AG8+25%*AG8 -> 56.241482 | AK8: =AH8+15%*AH8 -> 0 | AL8: =AI8+12%*AI8 -> 151.03498 | AM8: =AJ8+12%*AJ8 -> 62.99046 | AN8: =AK8+15%*AK8 -> 0 | AP8: IT Domestic | AQ8: 73.274617 | AR8: =AQ8+15%*AQ8 -> 84.265809 | AS8: =AR8+15%*AR8 -> 96.905681 | AT8: =AS8+15%*AS8 -> 111.44153 | AU8: =AT8+15%*AT8 -> 128.15776 | AV8: =AU8+15%*AU8 -> 147.38143 | AW8: =AV8+15%*AV8 -> 169.48864 | AX8: =AW8+15%*AW8 -> 194.91194 | AY8: =AX8+15%*AX8 -> 224.14873 | ... BG8: =BF8+15%*BF8 -> 685.67608
C9: ESDM | D9: ='ESDM Sector'!D19 -> 89.888065 | E9: =D9*20% -> 17.977613 | G9: =E9*5% -> 0.89888065 | I9: =E9-G9 -> 17.078732 | M9: ESDM | N9: ='ESDM Sector'!N37 -> 121.57442 | O9: ='ESDM Sector'!O37 -> 24.314883 | P9: ='ESDM Sector'!P37 -> 1.2157442 | Q9: ='ESDM Sector'!Q37 -> 157.41136 | R9: ='ESDM Sector'!R37 -> 31.482271 | S9: ='ESDM Sector'!S37 -> 1.901144 | T9: ='ESDM Sector'!T37 -> 200.46722 | U9: ='ESDM Sector'!U37 -> 40.093444 | ... AN9: ='ESDM Sector'!AN37 -> 6.0239917 | AP9: ESDM | AQ9: 120.47983 | AR9: =AQ9+12%*AQ9 -> 134.93741 | AS9: =AR9+12%*AR9 -> 151.1299 | AT9: =AS9+12%*AS9 -> 169.26549 | AU9: =AT9+12%*AT9 -> 189.57735 | AV9: =AU9+12%*AU9 -> 212.32663 | AW9: =AV9+12%*AV9 -> 237.80583 | AX9: =AW9+12%*AW9 -> 266.34253 | AY9: =AX9+12%*AX9 -> 298.30363 | ... BG9: =BF9+12%*BF9 -> 738.58881
C10: Start Ups | D10: 10 | E10: =D10*40% -> 4 | G10: 0.08 | I10: =E10-G10 -> 3.92 | M10: Start Up | N10: =D10+30%*D10 -> 13 | O10: =E10+30%*E10 -> 5.2 | P10: 0.10 | Q10: =N10+30%*N10 -> 16.9 | R10: =O10+30%*O10 -> 6.76 | S10: =P10+15%*P10 -> 0.115 | T10: =Q10+30%*Q10 -> 21.97 | U10: =R10+30%*R10 -> 8.788 | V10: =S10+15%*S10 -> 0.13225 | W10: =T10+30%*T10 -> 28.561 | X10: =U10+30%*U10 -> 11.4244 | Y10: 0.20 | Z10: =W10+20%*W10 -> 34.2732 | AA10: =X10+20%*X10 -> 13.70928 | AB10: =Y10+15%*Y10 -> 0.23 | AC10: =Z10+20%*Z10 -> 41.12784 | AD10: =AA10+25%*AA10 -> 17.1366 | AE10: =AB10+15%*AB10 -> 0.2645 | AF10: =AC10+20%*AC10 -> 49.353408 | AG10: =AD10+25%*AD10 -> 21.42075 | AH10: =AE10+15%*AE10 -> 0.304175 | AI10: =AF10+20%*AF10 -> 59.22409 | AJ10: =AG10+25%*AG10 -> 26.775938 | AK10: 0.47 | AL10: =AI10+20%*AI10 -> 71.068908 | AM10: =AJ10+20%*AJ10 -> 32.131125 | AN10: =AK10+15%*AK10 -> 0.5405 | AP10: Startups | AQ10: 32.131125 | AR10: =AQ10+20%*AQ10 -> 38.55735 | AS10: =AR10+20%*AR10 -> 46.26882 | AT10: =AS10+20%*AS10 -> 55.522584 | AU10: =AT10+20%*AT10 -> 66.627101 | AV10: =AU10+20%*AU10 -> 79.952521 | AW10: =AV10+20%*AV10 -> 95.943025 | AX10: =AW10+20%*AW10 -> 115.13163 | AY10: =AX10+20%*AX10 -> 138.15796 | ... BG10: =BF10+20%*BF10 -> 594.05392
C11: Other sub-sectors of digital economy: | M11: Other sub-sectors of digital economy: | AQ11: =AQ10*AP14/AP13 -> 4819668.8 | AR11: =AR10*AQ11/AQ10 -> 5783602.5 | AS11: =AS10*AR11/AR10 -> 6940323 | AT11: =AT10*AS11/AS10 -> 8328387.6 | AU11: =AU10*AT11/AT10 -> 9994065.1 | AV11: =AV10*AU11/AU10 -> 11992878 | AW11: =AW10*AV11/AV10 -> 14391454 | AX11: =AX10*AW11/AW10 -> 17269745 | AY11: =AY10*AX11/AX10 -> 20723693 | ... BG11: =BG10*BF11/BF10 -> 89108088
C12: Digital Communication Services | D12: 23 | E12: =D12*6.5% -> 1.495 | G12: =E12*5% -> 0.07475 | I12: =E12-G12 -> 1.42025 | M12: Digital Communication Services | N12: =D12+22.62%*D12 -> 28.2026 | O12: =E12+23.59%*E12 -> 1.8476705 | P12: =O12*5% -> 0.092383525 | Q12: =N12+22.62%*N12 -> 34.582028 | R12: =O12+23.59%*O12 -> 2.283536 | S12: =R12*5% -> 0.1141768 | T12: =Q12+22.62%*Q12 -> 42.404483 | U12: =R12+23.59%*R12 -> 2.8222221 | V12: =U12*5% -> 0.14111111 | W12: =T12+22.62%*T12 -> 51.996377 | X12: =U12+23.59%*U12 -> 3.4879843 | Y12: =X12*5% -> 0.17439922 | Z12: =W12+10%*W12 -> 57.196015 | AA12: =X12+15%*X12 -> 4.0111819 | AB12: =AA12*5% -> 0.2005591 | AC12: =Z12+10%*Z12 -> 62.915616 | AD12: =AA12+15%*AA12 -> 4.6128592 | AE12: =AD12*5% -> 0.23064296 | AF12: =AC12+10%*AC12 -> 69.207178 | AG12: =AD12+15%*AD12 -> 5.3047881 | AH12: =AG12*5% -> 0.26523941 | AI12: =AF12+10%*AF12 -> 76.127895 | AJ12: =AG12+15%*AG12 -> 6.1005063 | AK12: =AJ12*5% -> 0.30502532 | AL12: =AI12+10%*AI12 -> 83.740685 | AM12: =AJ12+15%*AJ12 -> 7.0155823 | AN12: =AM12*5% -> 0.35077911
C13: Government e-Market place | D13: 13 | E13: =D13*10% -> 1.3 | G13: =E13*5% -> 0.065 | I13: =E13-G13 -> 1.235 | M13: Government e-Market place | N13: =D13+17.76%*D13 -> 15.3088 | O13: =E13+18.8%*E13 -> 1.5444 | P13: =O13*5% -> 0.07722 | Q13: =N13+17.76%*N13 -> 18.027643 | R13: =O13+18.8%*O13 -> 1.8347472 | S13: =R13*5% -> 0.09173736 | T13: =Q13+17.76%*Q13 -> 21.229352 | U13: =R13+18.8%*R13 -> 2.1796797 | V13: =U13*5% -> 0.10898398 | W13: =T13+17.76%*T13 -> 24.999685 | X13: =U13+18.8%*U13 -> 2.5894595 | Y13: =X13*5% -> 0.12947297 | Z13: =W13+10%*W13 -> 27.499654 | AA13: =X13+15%*X13 -> 2.9778784 | AB13: =AA13*5% -> 0.14889392 | AC13: =Z13+10%*Z13 -> 30.249619 | AD13: =AA13+15%*AA13 -> 3.4245601 | AE13: =AD13*5% -> 0.17122801 | AF13: =AC13+10%*AC13 -> 33.274581 | AG13: =AD13+15%*AD13 -> 3.9382441 | AH13: =AG13*5% -> 0.19691221 | AI13: =AF13+10%*AF13 -> 36.602039 | AJ13: =AG13+15%*AG13 -> 4.5289808 | AK13: =AJ13*5% -> 0.22644904 | AL13: =AI13+10%*AI13 -> 40.262243 | AM13: =AJ13+15%*AJ13 -> 5.2083279 | AN13: =AM13*5% -> 0.26041639 | AP13: 28.427563 | BG13: =1000000 -> 1000000
C14: Direct Benefit Transfer | D14: 5.66 | E14: =D14*15% -> 0.849 | G14: =E14*5% -> 0.04245 | I14: =E14-G14 -> 0.80655 | M14: Direct Benefit Transfer | N14: =D14+21%*D14 -> 6.8486 | O14: =E14+24.5%*E14 -> 1.057005 | P14: =O14*5% -> 0.05285025 | Q14: =N14+21%*N14 -> 8.286806 | R14: =O14+24.5%*O14 -> 1.3159712 | S14: =R14*5% -> 0.065798561 | T14: =Q14+21%*Q14 -> 10.027035 | U14: =R14+24.5%*R14 -> 1.6383842 | V14: =U14*5% -> 0.081919209 | W14: =T14+21%*T14 -> 12.132713 | X14: =U14+24.5%*U14 -> 2.0397883 | Y14: =X14*5% -> 0.10198941 | Z14: =W14+10%*W14 -> 13.345984 | AA14: =X14+15%*X14 -> 2.3457565 | AB14: =AA14*5% -> 0.11728783 | AC14: =Z14+10%*Z14 -> 14.680582 | AD14: =AA14+15%*AA14 -> 2.69762 | AE14: =AD14*5% -> 0.134881 | AF14: =AC14+10%*AC14 -> 16.148641 | AG14: =AD14+15%*AD14 -> 3.102263 | AH14: =AG14*5% -> 0.15511315 | AI14: =AF14+10%*AF14 -> 17.763505 | AJ14: =AG14+15%*AG14 -> 3.5676025 | AK14: =AJ14*5% -> 0.17838012 | AL14: =AI14+10%*AI14 -> 19.539855 | AM14: =AJ14+15%*AJ14 -> 4.1027429 | AN14: =AM14*5% -> 0.20513714 | AP14: 4264134.5
C15: Tech-enabled healthcare | D15: 1 | E15: =D15*8% -> 0.08 | G15: =E15*5% -> 0.004 | I15: =E15-G15 -> 0.076 | M15: Tech-enabled healthcare | N15: =D15+49.5%*D15 -> 1.495 | O15: =E15+20%*E15 -> 0.096 | P15: =O15*5% -> 0.0048 | Q15: =N15+49.5%*N15 -> 2.235025 | R15: =O15+20%*O15 -> 0.1152 | S15: =R15*5% -> 0.00576 | T15: =Q15+49.5%*Q15 -> 3.3413624 | U15: =R15+20%*R15 -> 0.13824 | V15: =U15*5% -> 0.006912 | W15: =T15+49.5%*T15 -> 4.9953368 | X15: =U15+20%*U15 -> 0.165888 | Y15: =X15*5% -> 0.0082944 | Z15: =W15+10%*W15 -> 5.4948704 | AA15: =X15+15%*X15 -> 0.1907712 | AB15: =AA15*5% -> 0.00953856 | AC15: =Z15+10%*Z15 -> 6.0443575 | AD15: =AA15+15%*AA15 -> 0.21938688 | AE15: =AD15*5% -> 0.010969344 | AF15: =AC15+10%*AC15 -> 6.6487932 | AG15: =AD15+15%*AD15 -> 0.25229491 | AH15: =AG15*5% -> 0.012614746 | AI15: =AF15+10%*AF15 -> 7.3136725 | AJ15: =AG15+15%*AG15 -> 0.29013915 | AK15: =AJ15*5% -> 0.014506957 | AL15: =AI15+10%*AI15 -> 8.0450398 | AM15: =AJ15+15%*AJ15 -> 0.33366002 | AN15: =AM15*5% -> 0.016683001
C16: Customizable education platform for students | D16: 10 | E16: =D16*5% -> 0.5 | G16: =E16*5% -> 0.025 | I16: =E16-G16 -> 0.475 | M16: Customizable education platform for students | N16: =D16+36.78%*D16 -> 13.678 | O16: =E16+40%*E16 -> 0.7 | P16: =O16*5% -> 0.035 | Q16: =N16+36.78%*N16 -> 18.708768 | R16: =O16+40%*O16 -> 0.98 | S16: =R16*5% -> 0.049 | T16: =Q16+36.78%*Q16 -> 25.589853 | U16: =R16+40%*R16 -> 1.372 | V16: =U16*5% -> 0.0686 | W16: =T16+36.78%*T16 -> 35.001802 | X16: =U16+40%*U16 -> 1.9208 | Y16: =X16*5% -> 0.09604 | Z16: =W16+10%*W16 -> 38.501982 | AA16: =X16+15%*X16 -> 2.20892 | AB16: =AA16*5% -> 0.110446 | AC16: =Z16+10%*Z16 -> 42.35218 | AD16: =AA16+15%*AA16 -> 2.540258 | AE16: =AD16*5% -> 0.1270129 | AF16: =AC16+10%*AC16 -> 46.587398 | AG16: =AD16+15%*AD16 -> 2.9212967 | AH16: =AG16*5% -> 0.14606484 | AI16: =AF16+10%*AF16 -> 51.246138 | AJ16: =AG16+15%*AG16 -> 3.3594912 | AK16: =AJ16*5% -> 0.16797456 | AL16: =AI16+10%*AI16 -> 56.370751 | AM16: =AJ16+15%*AJ16 -> 3.8634149 | AN16: =AM16*5% -> 0.19317074
C17: Digitally enabled power distribution | D17: 1 | E17: =D17*8% -> 0.08 | G17: =E17*5% -> 0.004 | I17: =E17-G17 -> 0.076 | M17: Digitally enabled power distribution | N17: =D17+82%*D17 -> 1.82 | O17: =E17+96%*E17 -> 0.1568 | P17: =O17*5% -> 0.00784 | Q17: =N17+82%*N17 -> 3.3124 | R17: =O17+96%*O17 -> 0.307328 | S17: =R17*5% -> 0.0153664 | T17: =Q17+82%*Q17 -> 6.028568 | U17: =R17+96%*R17 -> 0.60236288 | V17: =U17*5% -> 0.030118144 | W17: =T17+82%*T17 -> 10.971994 | X17: =U17+96%*U17 -> 1.1806312 | Y17: =X17*5% -> 0.059031562 | Z17: =W17+10%*W17 -> 12.069193 | AA17: =X17+15%*X17 -> 1.3577259 | AB17: =AA17*5% -> 0.067886297 | AC17: =Z17+10%*Z17 -> 13.276112 | AD17: =AA17+15%*AA17 -> 1.5613848 | AE17: =AD17*5% -> 0.078069241 | AF17: =AC17+10%*AC17 -> 14.603724 | AG17: =AD17+15%*AD17 -> 1.7955925 | AH17: =AG17*5% -> 0.089779627 | AI17: =AF17+10%*AF17 -> 16.064096 | AJ17: =AG17+15%*AG17 -> 2.0649314 | AK17: =AJ17*5% -> 0.10324657 | AL17: =AI17+10%*AI17 -> 17.670506 | AM17: =AJ17+15%*AJ17 -> 2.3746711 | AN17: =AM17*5% -> 0.11873356
C18: Smart grids with distributed generation | D18: 0.25 | E18: =D18*8% -> 0.02 | G18: =E18*5% -> 0.001 | I18: =E18-G18 -> 0.019 | M18: Smart grids with distributed generation | N18: =D18+40%*D18 -> 0.35 | O18: =E18+40%*E18 -> 0.028 | P18: =O18*5% -> 0.0014 | Q18: =N18+40%*N18 -> 0.49 | R18: =O18+40%*O18 -> 0.0392 | S18: =R18*5% -> 0.00196 | T18: =Q18+40%*Q18 -> 0.686 | U18: =R18+40%*R18 -> 0.05488 | V18: =U18*5% -> 0.002744 | W18: =T18+40%*T18 -> 0.9604 | X18: =U18+40%*U18 -> 0.076832 | Y18: =X18*5% -> 0.0038416 | Z18: =W18+10%*W18 -> 1.05644 | AA18: =X18+15%*X18 -> 0.0883568 | AB18: =AA18*5% -> 0.00441784 | AC18: =Z18+10%*Z18 -> 1.162084 | AD18: =AA18+15%*AA18 -> 0.10161032 | AE18: =AD18*5% -> 0.005080516 | AF18: =AC18+10%*AC18 -> 1.2782924 | AG18: =AD18+15%*AD18 -> 0.11685187 | AH18: =AG18*5% -> 0.0058425934 | AI18: =AF18+10%*AF18 -> 1.4061216 | AJ18: =AG18+15%*AG18 -> 0.13437965 | AK18: =AJ18*5% -> 0.0067189824 | AL18: =AI18+10%*AI18 -> 1.5467338 | AM18: =AJ18+15%*AJ18 -> 0.1545366 | AN18: =AM18*5% -> 0.0077268298 | AT18: IT Exports | AU18: 2247.9439
C19: Digital payments | D19: 5 | E19: =D19*10% -> 0.5 | G19: =E19*5% -> 0.025 | I19: =E19-G19 -> 0.475 | M19: Digital payments | N19: =D19+62.66%*D19 -> 8.133 | O19: =E19+45%*E19 -> 0.725 | P19: =O19*5% -> 0.03625 | Q19: =N19+62.66%*N19 -> 13.229138 | R19: =O19+45%*O19 -> 1.05125 | S19: =R19*5% -> 0.0525625 | T19: =Q19+62.66%*Q19 -> 21.518516 | U19: =R19+45%*R19 -> 1.5243125 | V19: =U19*5% -> 0.076215625 | W19: =T19+62.66%*T19 -> 35.002017 | X19: =U19+45%*U19 -> 2.2102531 | Y19: =X19*5% -> 0.11051266 | Z19: =W19+10%*W19 -> 38.502219 | AA19: =X19+15%*X19 -> 2.5417911 | AB19: =AA19*5% -> 0.12708955 | AC19: =Z19+10%*Z19 -> 42.352441 | AD19: =AA19+15%*AA19 -> 2.9230598 | AE19: =AD19*5% -> 0.14615299 | AF19: =AC19+10%*AC19 -> 46.587685 | AG19: =AD19+15%*AD19 -> 3.3615187 | AH19: =AG19*5% -> 0.16807594 | AI19: =AF19+10%*AF19 -> 51.246454 | AJ19: =AG19+15%*AG19 -> 3.8657465 | AK19: =AJ19*5% -> 0.19328733 | AL19: =AI19+10%*AI19 -> 56.371099 | AM19: =AJ19+15%*AJ19 -> 4.4456085 | AN19: =AM19*5% -> 0.22228043 | AT19: IT Domestic | AU19: 685.67608
C20: Flow based lending and advanced credit (MSME's) | D20: 10 | E20: =D20*6% -> 0.6 | G20: =E20*5% -> 0.03 | I20: =E20-G20 -> 0.57 | M20: Flow based lending and advanced credit (MSME's) | N20: =D20+80%*D20 -> 18 | O20: =E20+70%*E20 -> 1.02 | P20: =O20*5% -> 0.051 | Q20: =N20+80%*N20 -> 32.4 | R20: =O20+70%*O20 -> 1.734 | S20: =R20*5% -> 0.0867 | T20: =Q20+80%*Q20 -> 58.32 | U20: =R20+70%*R20 -> 2.9478 | V20: =U20*5% -> 0.14739 | W20: =T20+80%*T20 -> 104.976 | X20: =U20+70%*U20 -> 5.01126 | Y20: =X20*5% -> 0.250563 | Z20: =W20+10%*W20 -> 115.4736 | AA20: =X20+15%*X20 -> 5.762949 | AB20: =AA20*5% -> 0.28814745 | AC20: =Z20+10%*Z20 -> 127.02096 | AD20: =AA20+15%*AA20 -> 6.6273913 | AE20: =AD20*5% -> 0.33136957 | AF20: =AC20+10%*AC20 -> 139.72306 | AG20: =AD20+15%*AD20 -> 7.6215001 | AH20: =AG20*5% -> 0.381075 | AI20: =AF20+10%*AF20 -> 153.69536 | AJ20: =AG20+15%*AG20 -> 8.7647251 | AK20: =AJ20*5% -> 0.43823625 | AL20: =AI20+10%*AI20 -> 169.0649 | AM20: =AJ20+15%*AJ20 -> 10.079434 | AN20: =AM20*5% -> 0.50397169 | AT20: ESDM | AU20: 738.58881
C21: Digital Farmer financing and insurance payouts | D21: 1 | E21: =D21*13% -> 0.13 | G21: =E21*5% -> 0.0065 | I21: =E21-G21 -> 0.1235 | M21: Digital Farmer financing and insurance payouts | N21: =D21+88%*D21 -> 1.88 | O21: =E21+75%*E21 -> 0.2275 | P21: =O21*5% -> 0.011375 | Q21: =N21+88%*N21 -> 3.5344 | R21: =O21+75%*O21 -> 0.398125 | S21: =R21*5% -> 0.01990625 | T21: =Q21+88%*Q21 -> 6.644672 | U21: =R21+75%*R21 -> 0.69671875 | V21: =U21*5% -> 0.034835938 | W21: =T21+88%*T21 -> 12.491983 | X21: =U21+75%*U21 -> 1.2192578 | Y21: =X21*5% -> 0.060962891 | Z21: =W21+10%*W21 -> 13.741182 | AA21: =X21+15%*X21 -> 1.4021465 | AB21: =AA21*5% -> 0.070107324 | AC21: =Z21+10%*Z21 -> 15.1153 | AD21: =AA21+15%*AA21 -> 1.6124685 | AE21: =AD21*5% -> 0.080623423 | AF21: =AC21+10%*AC21 -> 16.62683 | AG21: =AD21+15%*AD21 -> 1.8543387 | AH21: =AG21*5% -> 0.092716936 | AI21: =AF21+10%*AF21 -> 18.289513 | AJ21: =AG21+15%*AG21 -> 2.1324895 | AK21: =AJ21*5% -> 0.10662448 | AL21: =AI21+10%*AI21 -> 20.118464 | AM21: =AJ21+15%*AJ21 -> 2.452363 | AN21: =AM21*5% -> 0.12261815 | AT21: Startups | AU21: 594.05392
C22: Precision agriculture | D22: 1 | E22: =D22*9% -> 0.09 | G22: =E22*5% -> 0.0045 | I22: =E22-G22 -> 0.0855 | M22: Precision agriculture | N22: =D22+118%*D22 -> 2.18 | O22: =E22+85%*E22 -> 0.1665 | P22: =O22*5% -> 0.008325 | Q22: =N22+118%*N22 -> 4.7524 | R22: =O22+85%*O22 -> 0.308025 | S22: =R22*5% -> 0.01540125 | T22: =Q22+118%*Q22 -> 10.360232 | U22: =R22+85%*R22 -> 0.56984625 | V22: =U22*5% -> 0.028492313 | W22: =T22+118%*T22 -> 22.585306 | X22: =U22+85%*U22 -> 1.0542156 | Y22: =X22*5% -> 0.052710778 | Z22: =W22+10%*W22 -> 24.843836 | AA22: =X22+15%*X22 -> 1.2123479 | AB22: =AA22*5% -> 0.060617395 | AC22: =Z22+10%*Z22 -> 27.32822 | AD22: =AA22+15%*AA22 -> 1.3942001 | AE22: =AD22*5% -> 0.069710004 | AF22: =AC22+10%*AC22 -> 30.061042 | AG22: =AD22+15%*AD22 -> 1.6033301 | AH22: =AG22*5% -> 0.080166505 | AI22: =AF22+10%*AF22 -> 33.067146 | AJ22: =AG22+15%*AG22 -> 1.8438296 | AK22: =AJ22*5% -> 0.09219148 | AL22: =AI22+10%*AI22 -> 36.373861 | AM22: =AJ22+15%*AJ22 -> 2.120404 | AN22: =AM22*5% -> 0.1060202
C23: Universal agricultural marketplace | D23: 1 | E23: =D23*6% -> 0.06 | G23: =E23*5% -> 0.003 | I23: =E23-G23 -> 0.057 | M23: Universal agricultural marketplace | N23: =D23+118%*D23 -> 2.18 | O23: =E23+110%*E23 -> 0.126 | P23: =O23*5% -> 0.0063 | Q23: =N23+118%*N23 -> 4.7524 | R23: =O23+110%*O23 -> 0.2646 | S23: =R23*5% -> 0.01323 | T23: =Q23+118%*Q23 -> 10.360232 | U23: =R23+110%*R23 -> 0.55566 | V23: =U23*5% -> 0.027783 | W23: =T23+118%*T23 -> 22.585306 | X23: =U23+110%*U23 -> 1.166886 | Y23: =X23*5% -> 0.0583443 | Z23: =W23+10%*W23 -> 24.843836 | AA23: =X23+15%*X23 -> 1.3419189 | AB23: =AA23*5% -> 0.067095945 | AC23: =Z23+10%*Z23 -> 27.32822 | AD23: =AA23+15%*AA23 -> 1.5432067 | AE23: =AD23*5% -> 0.077160337 | AF23: =AC23+10%*AC23 -> 30.061042 | AG23: =AD23+15%*AD23 -> 1.7746877 | AH23: =AG23*5% -> 0.088734387 | AI23: =AF23+10%*AF23 -> 33.067146 | AJ23: =AG23+15%*AG23 -> 2.0408909 | AK23: =AJ23*5% -> 0.10204455 | AL23: =AI23+10%*AI23 -> 36.373861 | AM23: =AJ23+15%*AJ23 -> 2.3470245 | AN23: =AM23*5% -> 0.11735123
C24: Online talent platforms | D24: 1 | E24: =D24*5% -> 0.05 | G24: =E24*5% -> 0.0025 | I24: =E24-G24 -> 0.0475 | M24: Online talent platforms | N24: =D24+187%*D24 -> 2.87 | O24: =E24+23.59%*E24 -> 0.061795 | P24: =O24*5% -> 0.00308975 | Q24: =N24+187%*N24 -> 8.2369 | R24: =O24+23.59%*O24 -> 0.07637244 | S24: =R24*5% -> 0.003818622 | T24: =Q24+187%*Q24 -> 23.639903 | U24: =R24+23.59%*R24 -> 0.094388699 | V24: =U24*5% -> 0.004719435 | W24: =T24+187%*T24 -> 67.846522 | X24: =U24+23.59%*U24 -> 0.11665499 | Y24: =X24*5% -> 0.0058327497 | Z24: =W24+10%*W24 -> 74.631174 | AA24: =X24+15%*X24 -> 0.13415324 | AB24: =AA24*5% -> 0.0067076621 | AC24: =Z24+10%*Z24 -> 82.094291 | AD24: =AA24+15%*AA24 -> 0.15427623 | AE24: =AD24*5% -> 0.0077138114 | AF24: =AC24+10%*AC24 -> 90.30372 | AG24: =AD24+15%*AD24 -> 0.17741766 | AH24: =AG24*5% -> 0.0088708832 | AI24: =AF24+10%*AF24 -> 99.334092 | AJ24: =AG24+15%*AG24 -> 0.20403031 | AK24: =AJ24*5% -> 0.010201516 | AL24: =AI24+10%*AI24 -> 109.2675 | AM24: =AJ24+15%*AJ24 -> 0.23463486 | AN24: =AM24*5% -> 0.011731743
C25: End to end digital supply chain - Traditional Retail | D25: 1 | E25: =D25*8% -> 0.08 | G25: =E25*5% -> 0.004 | I25: =E25-G25 -> 0.076 | M25: End to end digital supply chain - Traditional Retail | N25: =D25+68.18%*D25 -> 1.6818 | O25: =E25+110%*E25 -> 0.168 | P25: =O25*5% -> 0.0084 | Q25: =N25+68.18%*N25 -> 2.8284512 | R25: =O25+110%*O25 -> 0.3528 | S25: =R25*5% -> 0.01764 | T25: =Q25+68.18%*Q25 -> 4.7568893 | U25: =R25+110%*R25 -> 0.74088 | V25: =U25*5% -> 0.037044 | W25: =T25+68.18%*T25 -> 8.0001364 | X25: =U25+110%*U25 -> 1.555848 | Y25: =X25*5% -> 0.0777924 | Z25: =W25+10%*W25 -> 8.8001501 | AA25: =X25+15%*X25 -> 1.7892252 | AB25: =AA25*5% -> 0.08946126 | AC25: =Z25+10%*Z25 -> 9.6801651 | AD25: =AA25+15%*AA25 -> 2.057609 | AE25: =AD25*5% -> 0.10288045 | AF25: =AC25+10%*AC25 -> 10.648182 | AG25: =AD25+15%*AD25 -> 2.3662503 | AH25: =AG25*5% -> 0.11831252 | AI25: =AF25+10%*AF25 -> 11.713 | AJ25: =AG25+15%*AG25 -> 2.7211879 | AK25: =AJ25*5% -> 0.13605939 | AL25: =AI25+10%*AI25 -> 12.8843 | AM25: =AJ25+15%*AJ25 -> 3.1293661 | AN25: =AM25*5% -> 0.1564683
C26: End to end digital supply chain - E-Commerce | D26: 1 | E26: =D26*8% -> 0.08 | G26: =E26*5% -> 0.004 | I26: =E26-G26 -> 0.076 | M26: End to end digital supply chain - E-Commerce | N26: =D26+105%*D26 -> 2.05 | O26: =E26+110%*E26 -> 0.168 | P26: =O26*5% -> 0.0084 | Q26: =N26+105%*N26 -> 4.2025 | R26: =O26+110%*O26 -> 0.3528 | S26: =R26*5% -> 0.01764 | T26: =Q26+105%*Q26 -> 8.615125 | U26: =R26+110%*R26 -> 0.74088 | V26: =U26*5% -> 0.037044 | W26: =T26+105%*T26 -> 17.661006 | X26: =U26+110%*U26 -> 1.555848 | Y26: =X26*5% -> 0.0777924 | Z26: =W26+10%*W26 -> 19.427107 | AA26: =X26+15%*X26 -> 1.7892252 | AB26: =AA26*5% -> 0.08946126 | AC26: =Z26+10%*Z26 -> 21.369818 | AD26: =AA26+15%*AA26 -> 2.057609 | AE26: =AD26*5% -> 0.10288045 | AF26: =AC26+10%*AC26 -> 23.506799 | AG26: =AD26+15%*AD26 -> 2.3662503 | AH26: =AG26*5% -> 0.11831252 | AI26: =AF26+10%*AF26 -> 25.857479 | AJ26: =AG26+15%*AG26 -> 2.7211879 | AK26: =AJ26*5% -> 0.13605939 | AL26: =AI26+10%*AI26 -> 28.443227 | AM26: =AJ26+15%*AJ26 -> 3.1293661 | AN26: =AM26*5% -> 0.1564683
C27: Efficient transport and logistics | D27: 1 | E27: =D27*8% -> 0.08 | G27: =E27*5% -> 0.004 | I27: =E27-G27 -> 0.076 | M27: Efficient transport and logistics | N27: =D27+116.57%*D27 -> 2.1657 | O27: =E27+141%*E27 -> 0.1928 | P27: =O27*5% -> 0.00964 | Q27: =N27+116.57%*N27 -> 4.6902565 | R27: =O27+141%*O27 -> 0.464648 | S27: =R27*5% -> 0.0232324 | T27: =Q27+116.57%*Q27 -> 10.157688 | U27: =R27+141%*R27 -> 1.1198017 | V27: =U27*5% -> 0.055990084 | W27: =T27+116.57%*T27 -> 21.998506 | X27: =U27+141%*U27 -> 2.698722 | Y27: =X27*5% -> 0.1349361 | Z27: =W27+10%*W27 -> 24.198357 | AA27: =X27+15%*X27 -> 3.1035304 | AB27: =AA27*5% -> 0.15517652 | AC27: =Z27+10%*Z27 -> 26.618192 | AD27: =AA27+15%*AA27 -> 3.5690599 | AE27: =AD27*5% -> 0.178453 | AF27: =AC27+10%*AC27 -> 29.280011 | AG27: =AD27+15%*AD27 -> 4.1044189 | AH27: =AG27*5% -> 0.20522094 | AI27: =AF27+10%*AF27 -> 32.208013 | AJ27: =AG27+15%*AG27 -> 4.7200817 | AK27: =AJ27*5% -> 0.23600409 | AL27: =AI27+10%*AI27 -> 35.428814 | AM27: =AJ27+15%*AJ27 -> 5.428094 | AN27: =AM27*5% -> 0.2714047
C28: Business digitization and IoT based analytics | D28: 1 | E28: =D28*9% -> 0.09 | G28: =E28*5% -> 0.0045 | I28: =E28-G28 -> 0.0855 | M28: Business digitization and IoT based analytics | N28: =D28+227%*D28 -> 3.27 | O28: =E28+200%*E28 -> 0.27 | P28: =O28*5% -> 0.0135 | Q28: =N28+227%*N28 -> 10.6929 | R28: =O28+200%*O28 -> 0.81 | S28: =R28*5% -> 0.0405 | T28: =Q28+227%*Q28 -> 34.965783 | U28: =R28+200%*R28 -> 2.43 | V28: =U28*5% -> 0.1215 | W28: =T28+227%*T28 -> 114.33811 | X28: =U28+200%*U28 -> 7.29 | Y28: =X28*5% -> 0.3645 | Z28: =W28+10%*W28 -> 125.77192 | AA28: =X28+15%*X28 -> 8.3835 | AB28: =AA28*5% -> 0.419175 | AC28: =Z28+10%*Z28 -> 138.34911 | AD28: =AA28+15%*AA28 -> 9.641025 | AE28: =AD28*5% -> 0.48205125 | AF28: =AC28+10%*AC28 -> 152.18402 | AG28: =AD28+15%*AD28 -> 11.087179 | AH28: =AG28*5% -> 0.55435894 | AI28: =AF28+10%*AF28 -> 167.40243 | AJ28: =AG28+15%*AG28 -> 12.750256 | AK28: =AJ28*5% -> 0.63751278 | AL28: =AI28+10%*AI28 -> 184.14267 | AM28: =AJ28+15%*AJ28 -> 14.662794 | AN28: =AM28*5% -> 0.73313969
C29: Total | D29: =SUM(D7:D28) -> 403.79806 | E29: =SUM(E7:E28) -> 110.40161 | F29: =SUM(F7:F28) -> 0 | G29: =SUM(G7:G28) -> 3.2030806 | H29: =SUM(H7:H28) -> 0 | I29: =SUM(I7:I28) -> 107.11853 | M29: Total | N29: =SUM(N7:N28) -> 502.39792 | O29: =SUM(O7:O28) -> 130.73215 | P29: =SUM(P7:P28) -> 4.1435177 | Q29: =SUM(Q7:Q28) -> 637.35907 | R29: =SUM(R7:R28) -> 155.21924 | S29: =SUM(S7:S28) -> 5.7755741 | T29: =SUM(T7:T28) -> 845.68297 | U29: =SUM(U7:U28) -> 186.49569 | ... AN29: =SUM(AN7:AN28) -> 21.07928
C31: Option 1 - Considering employment @ Growth assumptions as per revenue (At existing growth percentages considered for revenue estimation) | M31: (In Lakhs) | N31: 2022-23 | Q31: 2023-24 | T31: 2024-25 | W31: 2025-26 | Z31: 2026-27 | AC31: 2027-28 | AF31: 2028-29 | AI31: 2029-30 | AL31: 2030-31
C32: 2021-22 Data | M32: Employment | N32: India | O32: Karnataka | P32: Beyond Bengaluru | Q32: India | R32: Karnataka | S32: Beyond Bengaluru | T32: India | U32: Karnataka | V32: Beyond Bengaluru | W32: India | X32: Karnataka | Y32: Beyond Bengaluru | Z32: India | AA32: Karnataka | AB32: Beyond Bengaluru | AC32: India | AD32: Karnataka | AE32: Beyond Bengaluru | AF32: India | AG32: Karnataka | AH32: Beyond Bengaluru | AI32: India | AJ32: Karnataka | AK32: Beyond Bengaluru | AL32: India | AM32: Karnataka | AN32: Beyond Bengaluru
C33: Total Employment (Direct) | D33: In Millions | E33: In Lakhs | G33: Karnataka (In Lakhs) | I33: Beyond Bengaluru | K33: Only Bangalore | M33: IT Exports | N33: =E35+12%*E35 -> 5600000 | O33: =G35+12%*G35 -> 1489600 | P33: =I35+20%*I35 -> 120000 | Q33: =N33+12%*N33 -> 6272000 | R33: =O33+12%*O33 -> 1668352 | S33: =P33+20%*P33 -> 144000 | T33: =Q33+12%*Q33 -> 7024640 | U33: =R33+12%*R33 -> 1868554.2 | V33: =S33+20%*S33 -> 172800 | W33: =T33+12%*T33 -> 7867596.8 | X33: =U33+12%*U33 -> 2092780.7 | Y33: =V33+20%*V33 -> 207360 | Z33: =W33+10%*W33 -> 8654356.5 | AA33: =X33+10%*X33 -> 2302058.8 | AB33: =Y33+15%*Y33 -> 238464 | AC33: =Z33+10%*Z33 -> 9519792.1 | AD33: =AA33+10%*AA33 -> 2532264.7 | AE33: =AB33+15%*AB33 -> 274233.6 | AF33: =AC33+10%*AC33 -> 10471771 | AG33: =AD33+10%*AD33 -> 2785491.2 | AH33: =AE33+15%*AE33 -> 315368.64 | AI33: =AF33+10%*AF33 -> 11518948 | AJ33: =AG33+10%*AG33 -> 3064040.3 | AK33: =AH33+15%*AH33 -> 362673.94 | AL33: =AI33+10%*AI33 -> 12670843 | AM33: =AJ33+10%*AJ33 -> 3370444.3 | AN33: =AK33+15%*AK33 -> 417075.03
M34: IT Domestic | N34: =E36+12%*E36 -> 1120000 | O34: =G36+12%*G36 -> 324800 | P34: =I36+20%*I36 -> 60000 | Q34: =N34+12%*N34 -> 1254400 | R34: =O34+12%*O34 -> 363776 | S34: =P34+20%*P34 -> 72000 | T34: =Q34+12%*Q34 -> 1404928 | U34: =R34+12%*R34 -> 407429.12 | V34: =S34+20%*S34 -> 86400 | W34: =T34+12%*T34 -> 1573519.4 | X34: =U34+12%*U34 -> 456320.61 | Y34: =V34+20%*V34 -> 103680 | Z34: =W34+10%*W34 -> 1730871.3 | AA34: =X34+10%*X34 -> 501952.68 | AB34: =Y34+15%*Y34 -> 119232 | AC34: =Z34+10%*Z34 -> 1903958.4 | AD34: =AA34+10%*AA34 -> 552147.94 | AE34: =AB34+15%*AB34 -> 137116.8 | AF34: =AC34+10%*AC34 -> 2094354.3 | AG34: =AD34+10%*AD34 -> 607362.74 | AH34: =AE34+15%*AE34 -> 157684.32 | AI34: =AF34+10%*AF34 -> 2303789.7 | AJ34: =AG34+10%*AG34 -> 668099.01 | AK34: =AH34+15%*AH34 -> 181336.97 | AL34: =AI34+10%*AI34 -> 2534168.7 | AM34: =AJ34+10%*AJ34 -> 734908.91 | AN34: =AK34+15%*AK34 -> 208537.51
C35: India IT Exports | D35: 5 | E35: 5000000 | G35: 1330000 | I35: 100000 | K35: =G35-I35 -> 1230000 | M35: ESDM | N35: =E37+15%*E37 -> 805000 | O35: =G37+15%*G37 -> 161000 | P35: =I37+20%*I37 -> 72000 | Q35: =N35+15%*N35 -> 925750 | R35: =O35+15%*O35 -> 185150 | S35: =P35+20%*P35 -> 86400 | T35: =Q35+15%*Q35 -> 1064612.5 | U35: =R35+15%*R35 -> 212922.5 | V35: =S35+20%*S35 -> 103680 | W35: =T35+15%*T35 -> 1224304.4 | X35: =U35+15%*U35 -> 244860.88 | Y35: =V35+20%*V35 -> 124416 | Z35: =W35+12%*W35 -> 1371220.9 | AA35: =X35+12%*X35 -> 274244.18 | AB35: =Y35+15%*Y35 -> 143078.4 | AC35: =Z35+12%*Z35 -> 1535767.4 | AD35: =AA35+12%*AA35 -> 307153.48 | AE35: =AB35+15%*AB35 -> 164540.16 | AF35: =AC35+12%*AC35 -> 1720059.5 | AG35: =AD35+12%*AD35 -> 344011.9 | AH35: =AE35+15%*AE35 -> 189221.18 | AI35: =AF35+12%*AF35 -> 1926466.6 | AJ35: =AG35+12%*AG35 -> 385293.33 | AK35: =AH35+15%*AH35 -> 217604.36 | AL35: =AI35+12%*AI35 -> 2157642.6 | AM35: =AJ35+12%*AJ35 -> 431528.53 | AN35: =AK35+15%*AK35 -> 250245.02
C36: India IT Domestic | D36: 1 | E36: 1000000 | G36: 290000 | I36: 50000 | K36: =G36-I36 -> 240000 | M36: Start Up | N36: =E38+30%*E38 -> 1950000 | O36: =G38+30%*G38 -> 546000 | P36: =I38+20%*I38 -> 120000 | Q36: =N36+40%*N36 -> 2730000 | R36: =O36+40%*O36 -> 764400 | S36: =P36+20%*P36 -> 144000 | T36: =Q36+40%*Q36 -> 3822000 | U36: =R36+40%*R36 -> 1070160 | V36: =S36+20%*S36 -> 172800 | W36: =T36+40%*T36 -> 5350800 | X36: =U36+40%*U36 -> 1498224 | Y36: =V36+20%*V36 -> 207360 | Z36: =W36+25%*W36 -> 6688500 | AA36: =X36+25%*X36 -> 1872780 | AB36: =Y36+15%*Y36 -> 238464 | AC36: =Z36+25%*Z36 -> 8360625 | AD36: =AA36+25%*AA36 -> 2340975 | AE36: =AB36+15%*AB36 -> 274233.6 | AF36: =AC36+25%*AC36 -> 10450781 | AG36: =AD36+25%*AD36 -> 2926218.8 | AH36: =AE36+15%*AE36 -> 315368.64 | AI36: =AF36+25%*AF36 -> 13063477 | AJ36: =AG36+25%*AG36 -> 3657773.4 | AK36: =AH36+15%*AH36 -> 362673.94 | AL36: =AI36+25%*AI36 -> 16329346 | AM36: =AJ36+25%*AJ36 -> 4572216.8 | AN36: =AK36+15%*AK36 -> 417075.03
C37: India ESDM | D37: 0.7 | E37: 700000 | G37: =E37*20% -> 140000 | I37: 60000 | K37: =G37-I37 -> 80000 | M37: Total | N37: =SUM(N33:N36) -> 9475000 | O37: =SUM(O33:O36) -> 2521400 | P37: =SUM(P33:P36) -> 372000 | Q37: =SUM(Q33:Q36) -> 11182150 | R37: =SUM(R33:R36) -> 2981678 | S37: =SUM(S33:S36) -> 446400 | T37: =SUM(T33:T36) -> 13316180 | U37: =SUM(U33:U36) -> 3559065.9 | ... AN37: =SUM(AN33:AN36) -> 1292932.6
C38: India Start Up | D38: 1.5 | E38: 1500000 | G38: 420000 | I38: 100000 | K38: =G38-I38 -> 320000 | M38: Total in Lakhs | N38: =N37/100000 -> 94.75 | O38: =O37/100000 -> 25.214 | P38: =P37/100000 -> 3.72 | Q38: =Q37/100000 -> 111.8215 | R38: =R37/100000 -> 29.81678 | S38: =S37/100000 -> 4.464 | T38: =T37/100000 -> 133.1618 | U38: =U37/100000 -> 35.590659 | ... AN38: =AN37/100000 -> 12.929326
C40: Total | D40: =SUM(D35:D38) -> 8.2 | E40: =SUM(E35:E38) -> 8200000 | G40: =SUM(G35:G38) -> 2180000 | I40: =SUM(I35:I38) -> 310000 | K40: =G40-I40 -> 1870000 | O40: =O35/O37 -> 0.063853415
O41: =O36/O37 -> 0.21654636
C45: Growth assumptions made for the calculation (Revenue)
...

Sheet Final Employment Estimation
B2: Option 4 (Assuming on basis of ratio of revenue growth)
B5: Total Revenue | C5: 21-2022 | F5: 2022-23 | I5: 2023-24 | L5: 2024-25 | O5: 2025-26 | R5: 2026-27 | U5: 2027-28 | X5: 2028-29 | AA5: 2029-30 | AD5: 2030-31
B6: In USD Bn $
B7: Total Revenue | C7: India | D7: Karnataka | E7: Beyond Bengaluru | F7: India | G7: Karnataka | H7: Beyond Bengaluru | I7: India | J7: Karnataka | K7: Beyond Bengaluru | L7: India | M7: Karnataka | N7: Beyond Bengaluru | O7: India | P7: Karnataka | Q7: Beyond Bengaluru | R7: India | S7: Karnataka | T7: Beyond Bengaluru | U7: India | V7: Karnataka | W7: Beyond Bengaluru | X7: India | Y7: Karnataka | Z7: Beyond Bengaluru | AA7: India | AB7: Karnataka | AC7: Beyond Bengaluru | AD7: India | AE7: Karnataka | AF7: Beyond Bengaluru
B9: IT Exports | C9: ='Estimation of Revenue'!D7 -> 178 | D9: ='Estimation of Revenue'!E7 -> 67.64 | E9: ='Estimation of Revenue'!G7 -> 2 | F9: ='Estimation of Revenue'!N7 -> 199.36 | G9: ='Estimation of Revenue'!O7 -> 75.7568 | H9: ='Estimation of Revenue'!P7 -> 2.5 | I9: ='Estimation of Revenue'!Q7 -> 223.2832 | J9: ='Estimation of Revenue'!R7 -> 84.847616 | K9: ='Estimation of Revenue'!S7 -> 3.125 | L9: ='Estimation of Revenue'!T7 -> 250.07718 | M9: ='Estimation of Revenue'!U7 -> 95.02933 | ... O9: ='Estimation of Revenue'!W7 -> 280.08645 | P9: =O9*38% -> 106.43285 | Q9: ='Estimation of Revenue'!Y7 -> 4.8828125 | R9: ='Estimation of Revenue'!Z7 -> 308.09509 | S9: =R9*38% -> 117.07613 | T9: ='Estimation of Revenue'!AB7 -> 5.7714844 | U9: ='Estimation of Revenue'!AC7 -> 338.9046 | V9: =U9*38% -> 128.78375 | W9: ='Estimation of Revenue'!AE7 -> 6.8218945 | X9: ='Estimation of Revenue'!AF7 -> 372.79506 | Y9: =X9*38% -> 141.66212 | Z9: ='Estimation of Revenue'!AH7 -> 8.0634793 | AA9: ='Estimation of Revenue'!AI7 -> 410.07457 | AB9: =AA9*38% -> 155.82833 | AC9: ='Estimation of Revenue'!AK7 -> 9.5310326 | AD9: ='Estimation of Revenue'!AL7 -> 451.08202 | AE9: =AD9*38% -> 171.41117 | AF9: ='Estimation of Revenue'!AN7 -> 10.960687
B10: IT Domestic | C10: ='Estimation of Revenue'!D8 -> 49 | D10: ='Estimation of Revenue'!E8 -> 14.7 | E10: ='Estimation of Revenue'!G8 -> 0 | F10: ='Estimation of Revenue'!N8 -> 56.35 | G10: ='Estimation of Revenue'!O8 -> 16.905 | H10: ='Estimation of Revenue'!P8 -> 0 | I10: ='Estimation of Revenue'!Q8 -> 64.8025 | J10: ='Estimation of Revenue'!R8 -> 19.44075 | K10: ='Estimation of Revenue'!S8 -> 0 | L10: ='Estimation of Revenue'!T8 -> 74.522875 | M10: =L10*30% -> 22.356863 | N10: ='Estimation of Revenue'!V8 -> 0 | O10: ='Estimation of Revenue'!W8 -> 85.701306 | P10: =O10*30% -> 25.710392 | Q10: ='Estimation of Revenue'!Y8 -> 0 | R10: ='Estimation of Revenue'!Z8 -> 95.985463 | S10: =R10*30% -> 28.795639 | T10: ='Estimation of Revenue'!AB8 -> 0 | U10: ='Estimation of Revenue'!AC8 -> 107.50372 | V10: =U10*30% -> 32.251116 | W10: ='Estimation of Revenue'!AE8 -> 0 | X10: ='Estimation of Revenue'!AF8 -> 120.40416 | Y10: =X10*30% -> 36.121249 | Z10: ='Estimation of Revenue'!AH8 -> 0 | AA10: ='Estimation of Revenue'!AI8 -> 134.85266 | AB10: =AA10*30% -> 40.455799 | AC10: ='Estimation of Revenue'!AK8 -> 0 | AD10: ='Estimation of Revenue'!AL8 -> 151.03498 | AE10: =AD10*30% -> 45.310495 | AF10: ='Estimation of Revenue'!AN8 -> 0
B11: ESDM | C11: ='Estimation of Revenue'!D9 -> 89.888065 | D11: ='Estimation of Revenue'!E9 -> 17.977613 | E11: ='Estimation of Revenue'!G9 -> 0.89888065 | F11: ='Estimation of Revenue'!N9 -> 121.57442 | G11: ='Estimation of Revenue'!O9 -> 24.314883 | H11: ='Estimation of Revenue'!P9 -> 1.2157442 | I11: ='Estimation of Revenue'!Q9 -> 157.41136 | J11: ='Estimation of Revenue'!R9 -> 31.482271 | K11: ='Estimation of Revenue'!S9 -> 1.901144 | L11: ='Estimation of Revenue'!T9 -> 200.46722 | M11: =L11*20% -> 40.093444 | N11: ='Estimation of Revenue'!V9 -> 2.0070034 | O11: ='Estimation of Revenue'!W9 -> 314.92018 | P11: =O11*20% -> 62.984036 | Q11: ='Estimation of Revenue'!Y9 -> 3.2318251 | R11: ='Estimation of Revenue'!Z9 -> 356.44057 | S11: =R11*20% -> 71.288114 | T11: ='Estimation of Revenue'!AB9 -> 3.6987669 | U11: ='Estimation of Revenue'!AC9 -> 403.66948 | V11: =U11*20% -> 80.733896 | W11: ='Estimation of Revenue'!AE9 -> 4.229544 | X11: ='Estimation of Revenue'!AF9 -> 451.84746 | Y11: =X11*20% -> 90.369493 | Z11: ='Estimation of Revenue'!AH9 -> 4.6095996 | AA11: ='Estimation of Revenue'!AI9 -> 512.25185 | AB11: =AA11*20% -> 102.45037 | AC11: ='Estimation of Revenue'!AK9 -> 5.259206 | AD11: ='Estimation of Revenue'!AL9 -> 581.89605 | AE11: =AD11*20% -> 116.37921 | AF11: ='Estimation of Revenue'!AN9 -> 6.0239917
B12: Start Up | C12: ='Estimation of Revenue'!D10 -> 10 | D12: ='Estimation of Revenue'!E10 -> 4 | E12: ='Estimation of Revenue'!G10 -> 0.08 | F12: ='Estimation of Revenue'!N10 -> 13 | G12: ='Estimation of Revenue'!O10 -> 5.2 | H12: ='Estimation of Revenue'!P10 -> 0.10 | I12: ='Estimation of Revenue'!Q10 -> 16.9 | J12: ='Estimation of Revenue'!R10 -> 6.76 | K12: ='Estimation of Revenue'!S10 -> 0.115 | L12: ='Estimation of Revenue'!T10 -> 21.97 | M12: ='Estimation of Revenue'!U10 -> 8.788 | ... O12: ='Estimation of Revenue'!W10 -> 28.561 | P12: =O12*40% -> 11.4244 | Q12: ='Estimation of Revenue'!Y10 -> 0.20 | R12: ='Estimation of Revenue'!Z10 -> 34.2732 | S12: =R12*40% -> 13.70928 | T12: ='Estimation of Revenue'!AB10 -> 0.23 | U12: ='Estimation of Revenue'!AC10 -> 41.12784 | V12: =U12*40% -> 16.451136 | W12: ='Estimation of Revenue'!AE10 -> 0.2645 | X12: ='Estimation of Revenue'!AF10 -> 49.353408 | Y12: =X12*40% -> 19.741363 | Z12: ='Estimation of Revenue'!AH10 -> 0.304175 | AA12: ='Estimation of Revenue'!AI10 -> 59.22409 | AB12: =AA12*40% -> 23.689636 | AC12: ='Estimation of Revenue'!AK10 -> 0.47 | AD12: ='Estimation of Revenue'!AL10 -> 71.068908 | AE12: =AD12*40% -> 28.427563 | AF12: ='Estimation of Revenue'!AN10 -> 0.5405
B14: Estimated employment projections based on revenue
B15: Total Employment | C15: 21-2022 | F15: 2022-23 | I15: 2023-24 | L15: 2024-25 | O15: 2025-26 | R15: 2026-27 | U15: 2027-28 | X15: 2028-29 | AA15: 2029-30 | AD15: 2030-31
B17: Total Employment | C17: India | D17: Karnataka | E17: Beyond Bengaluru | F17: India | G17: Karnataka | H17: Beyond Bengaluru | I17: India | J17: Karnataka | K17: Beyond Bengaluru | L17: India | M17: Karnataka | N17: Beyond Bengaluru | O17: India | P17: Karnataka | Q17: Beyond Bengaluru | R17: India | S17: Karnataka | T17: Beyond Bengaluru | U17: India | V17: Karnataka | W17: Beyond Bengaluru | X17: India | Y17: Karnataka | Z17: Beyond Bengaluru | AA17: India | AB17: Karnataka | AC17: Beyond Bengaluru | AD17: India | AE17: Karnataka | AF17: Beyond Bengaluru
B18: (Direct)
B19: IT Exports | C19: 3510000 | D19: ='Estimation of Revenue'!G35 -> 1330000 | E19: ='Beyond Bengaluru Workings'!D20 -> 131578.95 | F19: =F9*C19/C9 -> 3931200 | G19: =G9*D19/D9 -> 1489600 | H19: =H9*E19/E9 -> 164473.68 | I19: =I9*F19/F9 -> 4402944 | J19: =J9*G19/G9 -> 1668352 | K19: =K9*H19/H9 -> 205592.11 | L19: =L9*I19/I9 -> 4931297.3 | M19: =M9*J19/J9 -> 1868554.2 | ... AF19: =AF9*AC19/AC9 -> 721097.86
B20: IT Domestic | C20: 990000 | D20: ='Estimation of Revenue'!G36 -> 290000 | E20: 0 | F20: =F10*C20/C10 -> 1138500 | G20: =G10*D20/D10 -> 333500 | H20: 0 | I20: =I10*F20/F10 -> 1309275 | J20: =J10*G20/G10 -> 383525 | K20: 0 | L20: =L10*I20/I10 -> 1505666.3 | M20: =M10*J20/J10 -> 441053.75 | N20: 0 | O20: =O10*L20/L10 -> 1731516.2 | P20: =P10*M20/M10 -> 507211.81 | Q20: 0 | R20: =R10*O20/O10 -> 1939298.1 | S20: =S10*P20/P10 -> 568077.23 | T20: 0 | U20: =U10*R20/R10 -> 2172013.9 | V20: =V10*S20/S10 -> 636246.5 | W20: 0 | X20: =X10*U20/U10 -> 2432655.6 | Y20: =Y10*V20/V10 -> 712596.08 | Z20: 0 | AA20: =AA10*X20/X10 -> 2724574.2 | AB20: =AB10*Y20/Y10 -> 798107.61 | AC20: 0 | AD20: =AD10*AA20/AA10 -> 3051523.2 | AE20: =AE10*AB20/AB10 -> 893880.52 | AF20: 0
B21: ESDM | C21: ='Estimation of Revenue'!E37 -> 700000 | D21: ='Estimation of Revenue'!G37 -> 140000 | E21: ='Estimation of Revenue'!I37 -> 60000 | F21: =F11*C21/C11 -> 946756.3 | G21: =G11*D21/D11 -> 189351.26 | H21: =H11*E21/E11 -> 81150.54 | I21: =I11*F21/F11 -> 1225835.1 | J21: =J11*G21/G11 -> 245167.03 | K21: =K11*H21/H11 -> 126900.76 | L21: =L11*I21/I11 -> 1561131.1 | M21: =M11*J21/J11 -> 312226.22 | ... AF21: =AF11*AC21/AC11 -> 402099.55
B22: Start Up | C22: 1060000 | D22: ='Estimation of Revenue'!G38 -> 420000 | E22: ='Estimation of Revenue'!I38 -> 100000 | F22: =F12*C22/C12 -> 1378000 | G22: =G12*D22/D12 -> 546000 | H22: =H12*E22/E12 -> 125000 | I22: =I12*F22/F12 -> 1791400 | J22: =J12*G22/G12 -> 709800 | K22: =K12*H22/H12 -> 143750 | L22: =L12*I22/I12 -> 2328820 | M22: =M12*J22/J12 -> 922740 | ... AF22: =AF12*AC22/AC12 -> 675625
B24: Total | C24: =SUM(C19:C22) -> 6260000 | D24: =SUM(D19:D22) -> 2180000 | E24: =SUM(E19:E22) -> 291578.95 | F24: =SUM(F19:F22) -> 7394456.3 | G24: =SUM(G19:G22) -> 2558451.3 | H24: =SUM(H19:H22) -> 370624.22 | I24: =SUM(I19:I22) -> 8729454.1 | J24: =SUM(J19:J22) -> 3006844 | ... AF24: =SUM(AF19:AF22) -> 1798822.4
B25: Total (In Millions) | C25: =C24/1000000 -> 6.26 | D25: =D24/1000000 -> 2.18 | E25: =E24/1000000 -> 0.29157895 | F25: =F24/1000000 -> 7.3944563 | G25: =G24/1000000 -> 2.5584513 | H25: =H24/1000000 -> 0.37062422 | I25: =I24/1000000 -> 8.7294541 | J25: =J24/1000000 -> 3.006844 | ... AF25: =AF24/1000000 -> 1.7988224
AC27: =AC25/AB25*100 -> 21.904393
Q28: =Q25/P25*100 -> 18.343906 | AC28: =AC19+AC22 -> 1214541.6
E29: =E25/D25*100 -> 13.375181 | F29: =F25/E25*100 -> 2536.0049 | G29: =G25/F25*100 -> 34.599586 | H29: =H25/G25*100 -> 14.486273 | I29: =I25/H25*100 -> 2355.3383 | J29: =J25/I25*100 -> 34.444812 | K29: =K25/J25*100 -> 15.838629 | L29: =L25/K25*100 -> 2168.4135 | ... AF29: =AF25/AE25*100 -> 22.056508
D31: =D19/1000000 -> 1.33 | E31: =E19/1000000 -> 0.13157895 | F31: =F19/1000000 -> 3.9312 | G31: =G19/1000000 -> 1.4896 | H31: =H19/1000000 -> 0.16447368 | I31: =I19/1000000 -> 4.402944 | J31: =J19/1000000 -> 1.668352 | K31: =K19/1000000 -> 0.20559211 | ... AF31: =AF19/1000000 -> 0.72109786
D32: =D20/1000000 -> 0.29 | E32: =E20/1000000 -> 0 | F32: =F20/1000000 -> 1.1385 | G32: =G20/1000000 -> 0.3335 | H32: =H20/1000000 -> 0 | I32: =I20/1000000 -> 1.309275 | J32: =J20/1000000 -> 0.383525 | K32: =K20/1000000 -> 0 | ... AF32: =AF20/1000000 -> 0
D33: =D21/1000000 -> 0.14 | E33: =E21/1000000 -> 0.06 | F33: =F21/1000000 -> 0.9467563 | G33: =G21/1000000 -> 0.18935126 | H33: =H21/1000000 -> 0.08115054 | I33: =I21/1000000 -> 1.2258351 | J33: =J21/1000000 -> 0.24516703 | K33: =K21/1000000 -> 0.12690076 | ... AF33: =AF21/1000000 -> 0.40209955
D34: =D22/1000000 -> 0.42 | E34: =E22/1000000 -> 0.1 | F34: =F22/1000000 -> 1.378 | G34: =G22/1000000 -> 0.546 | H34: =H22/1000000 -> 0.125 | I34: =I22/1000000 -> 1.7914 | J34: =J22/1000000 -> 0.7098 | K34: =K22/1000000 -> 0.14375 | ... AF34: =AF22/1000000 -> 0.675625
D35: =D23/1000000 -> 0 | E35: =E23/1000000 -> 0 | F35: =F23/1000000 -> 0 | G35: =G23/1000000 -> 0 | H35: =H23/1000000 -> 0 | I35: =I23/1000000 -> 0 | J35: =J23/1000000 -> 0 | K35: =K23/1000000 -> 0 | ... AF35: =AF23/1000000 -> 0
D36: =D24/1000000 -> 2.18 | E36: =E24/1000000 -> 0.29157895 | F36: =F24/1000000 -> 7.3944563 | G36: =G24/1000000 -> 2.5584513 | H36: =H24/1000000 -> 0.37062422 | I36: =I24/1000000 -> 8.7294541 | J36: =J24/1000000 -> 3.006844 | K36: =K24/1000000 -> 0.47624287 | ... AF36: =AF24/1000000 -> 1.7988224

Sheet Beyond Bengaluru Workings
B2: Beyond Bengaluru Workings (As per Beyond Bengaluru Report)
B5: Total Revenue | C5: 2020-21 | D5: 2021-22 | E5: 2022-23 | F5: 2023-24 | G5: 2024-25 | H5: 2025-26 | I5: 2026-27 | J5: 2027-28 | K5: 2028-29 | L5: 2029-30
B6: In USD Bn $
B7: Total Revenue | C7: Beyond Bengaluru | D7: Beyond Bengaluru | E7: Beyond Bengaluru | F7: Beyond Bengaluru | G7: Beyond Bengaluru | H7: Beyond Bengaluru | I7: Beyond Bengaluru | J7: Beyond Bengaluru | K7: Beyond Bengaluru | L7: Beyond Bengaluru
B9: Size of IT Industry | C9: 1.14 | D9: 2 | E9: =D9+25%*D9 -> 2.5 | F9: =E9+25%*E9 -> 3.125 | G9: =F9+25%*F9 -> 3.90625 | H9: =G9+25%*G9 -> 4.8828125 | I9: =H9+18.2%*H9 -> 5.7714844 | J9: =I9+18.2%*I9 -> 6.8218945 | K9: =J9+18.2%*J9 -> 8.0634793 | L9: =K9+18.2%*K9 -> 9.5310326
B10: ESDM | D10: ='Estimation of Revenue'!G9 -> 0.89888065 | E10: ='Estimation of Revenue'!P9 -> 1.2157442 | F10: ='Final Employment Estimation'!K11 -> 1.901144 | G10: ='Estimation of Revenue'!V9 -> 2.0070034 | H10: ='Final Employment Estimation'!Q11 -> 3.2318251 | I10: ='Final Employment Estimation'!T11 -> 3.6987669 | J10: ='Final Employment Estimation'!W11 -> 4.229544 | K10: ='Final Employment Estimation'!Z11 -> 4.6095996 | L10: ='Final Employment Estimation'!AC11 -> 5.259206
B11: Startups | D11: ='Final Employment Estimation'!E12 -> 0.08 | E11: ='Final Employment Estimation'!H12 -> 0.10 | F11: ='Final Employment Estimation'!K12 -> 0.115 | G11: ='Final Employment Estimation'!N12 -> 0.13225 | H11: ='Final Employment Estimation'!Q12 -> 0.20 | I11: ='Final Employment Estimation'!T12 -> 0.23 | J11: ='Final Employment Estimation'!W12 -> 0.2645 | K11: ='Final Employment Estimation'!Z12 -> 0.304175 | L11: ='Final Employment Estimation'!AC12 -> 0.47
B12: Total | C12: =SUM(C9:C11) -> 1.14 | D12: =SUM(D9:D11) -> 2.8988806 | E12: =SUM(E9:E11) -> 3.7157442 | F12: =SUM(F9:F11) -> 5.141144 | G12: =SUM(G9:G11) -> 6.0455034 | H12: =SUM(H9:H11) -> 8.1146376 | I12: =SUM(I9:I11) -> 9.7002513 | J12: =SUM(J9:J11) -> 11.315939 | ... L12: =SUM(L9:L11) -> 14.790239
B15: Total Approximate number of employees
B16: Total Employment | C16: 2020-21 | D16: 2021-22 | E16: 2022-23 | F16: 2023-24 | G16: 2024-25 | H16: 2025-26 | I16: 2026-27 | J16: 2027-28 | K16: 2028-29 | L16: 2029-30
B18: Total Employment | C18: Beyond Bengaluru | D18: Beyond Bengaluru | E18: Beyond Bengaluru | F18: Beyond Bengaluru | G18: Beyond Bengaluru | H18: Beyond Bengaluru | I18: Beyond Bengaluru | J18: Beyond Bengaluru | K18: Beyond Bengaluru | L18: Beyond Bengaluru
B20: IT Industry | C20: 75000 | D20: =D9*C20/C9 -> 131578.95 | E20: =E9*D20/D9 -> 164473.68 | F20: =F9*E20/E9 -> 205592.11 | G20: =G9*F20/F9 -> 256990.13 | H20: =H9*G20/G9 -> 321237.66 | I20: =I9*H20/H9 -> 379702.92 | J20: =J9*I20/I9 -> 448808.85 | K20: =K9*J20/J9 -> 530492.06 | L20: =L9*K20/K9 -> 627041.62
B21: ESDM | D21: ='Final Employment Estimation'!E21 -> 60000 | E21: ='Final Employment Estimation'!H21 -> 81150.54 | F21: ='Final Employment Estimation'!K21 -> 126900.76 | G21: ='Final Employment Estimation'!N21 -> 133966.84 | H21: ='Final Employment Estimation'!Q21 -> 215723.31 | I21: ='Final Employment Estimation'!T21 -> 246891.53 | J21: ='Final Employment Estimation'!W21 -> 282320.73 | K21: ='Final Employment Estimation'!Z21 -> 307689.32 | L21: ='Final Employment Estimation'!AC21 -> 351050.34
B22: Startups | D22: ='Final Employment Estimation'!E22 -> 100000 | E22: ='Final Employment Estimation'!H22 -> 125000 | F22: ='Final Employment Estimation'!K22 -> 143750 | G22: ='Final Employment Estimation'!N22 -> 165312.5 | H22: ='Final Employment Estimation'!Q22 -> 250000 | I22: ='Final Employment Estimation'!T22 -> 287500 | J22: ='Final Employment Estimation'!W22 -> 330625 | K22: ='Final Employment Estimation'!Z22 -> 380218.75 | L22: ='Final Employment Estimation'!AC22 -> 587500
B23: Total | C23: =SUM(C20:C22) -> 75000 | D23: =SUM(D20:D22) -> 291578.95 | E23: =SUM(E20:E22) -> 370624.22 | F23: =SUM(F20:F22) -> 476242.87 | G23: =SUM(G20:G22) -> 556269.47 | H23: =SUM(H20:H22) -> 786960.97 | I23: =SUM(I20:I22) -> 914094.44 | J23: =SUM(J20:J22) -> 1061754.6 | ... L23: =SUM(L20:L22) -> 1565592
B24: Total (In Millions) | C24: =C23/1000000 -> 0.075 | D24: =D23/1000000 -> 0.29157895 | E24: =E23/1000000 -> 0.37062422 | F24: =F23/1000000 -> 0.47624287 | G24: =G23/1000000 -> 0.55626947 | H24: =H23/1000000 -> 0.78696097 | I24: =I23/1000000 -> 0.91409444 | J24: =J23/1000000 -> 1.0617546 | ... L24: =L23/1000000 -> 1.565592

Sheet Startups and GDP Calculation
B5: CAGR % | C5: Particulars | D5: FY 21-22 | E5: FY 22-23 | F5: FY 23-24 | G5: FY 24-25 | H5: FY 25-26 | I5: FY 26-27 | J5: FY 27-28 | K5: FY 28-29 | L5: FY 29-30 | M5: FY 30-31 | N5: FY 31-32 | O5: FY 32-33 | P5: FY 33-34 | Q5: FY 34-35 | R5: FY 35-36 | S5: FY 36-37 | T5: FY 37-38 | U5: FY 38-39 | V5: FY 39-40 | W5: FY 40-41 | X5: FY 41-42 | Y5: FY 42-43 | Z5: FY 43-44 | AA5: FY 44-45 | AB5: FY 45-46 | AC5: FY 46-47
B8: 22% (Till 2026) & 10.67% from 2026 to 2030 | C8: Number of Unicorns | D8: 37 | E8: =D8+22%*D8 -> 45.14 | F8: =E8+22%*E8 -> 55.0708 | G8: =F8+22%*F8 -> 67.186376 | H8: =G8+22%*G8 -> 81.967379 | I8: 100 | J8: =I8+10.67%*I8 -> 110.67 | K8: =J8+10.67%*J8 -> 122.47849 | L8: =K8+10.67%*K8 -> 135.54694 | M8: =L8+10.67%*L8 -> 150.0098 | N8: =M8+10.67%*M8 -> 166.01585 | O8: =N8+10.67%*N8 -> 183.72974 | P8: =O8+10.67%*O8 -> 203.3337 | Q8: =P8+10.67%*P8 -> 225.02941 | ... AC8: =AB8+10.67%*AB8 -> 759.62316
B10: 13.97% till the year 2030 | C10: Number of start-ups | D10: 13000 | E10: =D10+13.97%*D10 -> 14816.1 | F10: =E10+13.97%*E10 -> 16885.909 | G10: =F10+13.97%*F10 -> 19244.871 | H10: =G10+13.97%*G10 -> 21933.379 | I10: =H10+13.97%*H10 -> 24997.472 | J10: =I10+13.97%*I10 -> 28489.619 | K10: =J10+13.97%*J10 -> 32469.619 | L10: =K10+13.97%*K10 -> 37005.625 | ... AC10: =AB10+13.97%*AB10 -> 341748.85
C12: Contribution of startups to state GDP | D12: =D13/D14 -> 0.015209125 | E12: =E13/E14 -> 0.018055556 | F12: =F13/F14 -> 0.021435819 | G12: =G13/G14 -> 0.025448918 | H12: =H13/H14 -> 0.030213327 | I12: =I13/I14 -> 0.033110496 | J12: =J13/J14 -> 0.037797369 | K12: =K13/K14 -> 0.043147682 | ... AC12: =AC13/AC14 -> 0.23361166
B13: Till 2025 - 30% and Post 2025 - 20% | C13: Revenue estimation for Startups (In USD Bn) | D13: ='Estimation of Revenue'!E10 -> 4 | E13: ='Estimation of Revenue'!O10 -> 5.2 | F13: ='Estimation of Revenue'!R10 -> 6.76 | G13: ='Estimation of Revenue'!U10 -> 8.788 | H13: ='Estimation of Revenue'!X10 -> 11.4244 | I13: ='Estimation of Revenue'!AA10 -> 13.70928 | J13: ='Estimation of Revenue'!AD10 -> 17.1366 | K13: ='Estimation of Revenue'!AG10 -> 21.42075 | L13: ='Estimation of Revenue'!AJ10 -> 26.775938 | M13: ='Estimation of Revenue'!AM10 -> 32.131125 | N13: =M13+20%*M13 -> 38.55735 | O13: =N13+20%*N13 -> 46.26882 | P13: =O13+20%*O13 -> 55.522584 | Q13: =P13+20%*P13 -> 66.627101 | R13: =Q13+20%*Q13 -> 79.952521 | S13: =R13+20%*R13 -> 95.943025 | T13: =S13+20%*S13 -> 115.13163 | U13: =T13+20%*T13 -> 138.15796 | ... AC13: =AB13+20%*AB13 -> 594.05392
B14: Assumed at growth of 9.5% every year | C14: Assumptions for State GDP (In USD Bn) | D14: 263 | E14: 288 | F14: =E14+9.5%*E14 -> 315.36 | G14: =F14+9.5%*F14 -> 345.3192 | H14: =G14+9.5%*G14 -> 378.12452 | I14: =H14+9.5%*H14 -> 414.04635 | J14: =I14+9.5%*I14 -> 453.38076 | K14: =J14+9.5%*J14 -> 496.45193 | L14: =K14+9.5%*K14 -> 543.61486 | M14: =L14+9.5%*L14 -> 595.25827 | ... AC14: =AB14+9.5%*AB14 -> 2542.9121
C15: Assumptions for Global GDP (In USD Bn) | I15: 129729 | J15: 136383 | K15: =J15+5%*J15 -> 143202.15 | L15: =K15+5%*K15 -> 150362.26 | M15: =L15+5%*L15 -> 157880.37 | N15: =M15+5%*M15 -> 165774.39 | O15: =N15+5%*N15 -> 174063.11 | P15: =O15+5%*O15 -> 182766.26 | Q15: =P15+5%*P15 -> 191904.58 | R15: =Q15+5%*Q15 -> 201499.81 | ... AC15: =AB15+5%*AB15 -> 344633.05
C16: Contribution of startups to Global GDP | I16: =I13/I15 -> 0.00010567629 | J16: =J15-I15 -> 6654 | K16: =J16/I15*100 -> 5.1291539 | L16: =L13/L15 -> 0.00017807619 | M16: =M13/M15 -> 0.00020351564 | N16: =N13/N15 -> 0.00023258931 | O16: =O13/O15 -> 0.00026581635 | P16: =P13/P15 -> 0.00030379011 | Q16: =Q13/Q15 -> 0.0003471887 | R16: =R13/R15 -> 0.00039678709 | S16: =S13/S15 -> 0.00045347096 | ... AC16: =AC13/AC15 -> 0.0017237288
C17: Revenue - GCC | D17: =64.6+17.1 -> 81.7 | E17: 92 | F17: 103.65 | G17: 116.77 | H17: =101.65+29.91 -> 131.56 | I17: 145.31 | J17: 160.51 | K17: 177.31 | L17: 195.89
C18: Contribution of GCC to State GDP | D18: =D17/D14 -> 0.31064639 | E18: =E17/E14 -> 0.31944444 | F18: =F17/F14 -> 0.32867199 | G18: =G17/G14 -> 0.33815091 | H18: =H17/H14 -> 0.34792771 | I18: =I17/I14 -> 0.35095104 | J18: =J17/J14 -> 0.35402914 | K18: =K17/K14 -> 0.35715442 | L18: =L17/L14 -> 0.36034703
C19: Revenue - ESDM | D19: 17.98 | E19: 24.31 | F19: 31.48 | G19: 40.09 | H19: 63.7 | I19: 72.19 | J19: 81.95 | K19: 92.19 | L19: 105.18
C20: Contribution of ESDM to State GDP | D20: =D19/D14 -> 0.068365019 | E20: =E19/E14 -> 0.084409722 | F20: =F19/F14 -> 0.099822425 | G20: =G19/G14 -> 0.11609548 | H20: =H19/H14 -> 0.16846302 | I20: =I19/I14 -> 0.17435246 | J20: =J19/J14 -> 0.18075315 | K20: =K19/K14 -> 0.18569774 | L20: =L19/L14 -> 0.19348257
C21: Revenue from Beyond Bengaluru (Projected) | D21: ='Estimation of Revenue'!G29 -> 3.2030806 | I21: ='Estimation of Revenue'!AB29 -> 11.73232 | M21: 14.79
C22: Contribution of Beyond Bengaluru to State GDP | D22: =D21/D14 -> 0.012179014 | I22: =I21/I14 -> 0.028335765 | J22: =J21/J14 -> 0 | K22: =K21/K14 -> 0 | L22: =L21/L14 -> 0 | M22: =M21/M14 -> 0.024846358
B23: https://www.icicidirect.com/calculators/cagr-calculator
B25: Global GDP 1985-2027 | Statista
C32: BB Employment share calculation | D32: 21-22 | E32: 25-26 | F32: 29-30
C34: Karnataka | D34: 2.94 | E34: 5.72 | F34: 9.55
C35: Beyond Bengaluru | D35: 0.29 | E35: 0.81 | F35: 1.56
D37: =D35/D34*100 -> 9.8639456 | E37: =E35/E34*100 -> 14.160839 | F37: =F35/F34*100 -> 16.335079

Sheet Sheet1
D4: Revenue (In USD Bn) | E4: 11
D5: Employment (In Millions) | E5: 0.2
D6: Number of Unicorns | E6: 100
D31: Revenue (In USD Bn) | E31: 0.2
D32: Employment (In Millions) | E32: 0.25

Sheet Sheet2
C3: 2021-22 | D3: 2022-23 | E3: 2026-27 | F3: 2029-30
B4: India | C4: 400 | D4: 500 | E4: 1000 | F4: 3000
B5: Karnataka | C5: 110 | D5: 130 | E5: 250 | F5: 500

Sheet ESDM Sector
C1: Investment estimation for ESDM sector (Generate revenue in US $ Bn)
C2: 2021-22 Data
C3: Total Revenue on investment India level | M3: ESDM Estimation of values (2022-2030)
C4: In USD Bn $
C5: Total Revenue | D5: India | E5: Karnataka | G5: Beyond Bengaluru | I5: Bangalore | M5: (In Bn $ USD) | N5: 2022-23 | Q5: 2023-24 | T5: 2024-25 | W5: 2025-26 | Z5: 2026-27 | AC5: 2027-28 | AF5: 2028-29 | AI5: 2029-30 | AL5: 2030-31
C6: ESDM Revenue (Excluding Consumer electronics) | D6: =90-10.5 -> 79.5 | E6: =D6*20% -> 15.9 | G6: =E6*5% -> 0.795 | I6: =E6-G6 -> 15.105 | M6: Revenue | N6: India | O6: Karnataka | P6: Beyond Bengaluru | Q6: India | R6: Karnataka | S6: Beyond Bengaluru | T6: India | U6: Karnataka | V6: Beyond Bengaluru | W6: India | X6: Karnataka | Y6: Beyond Bengaluru | Z6: India | AA6: Karnataka | AB6: Beyond Bengaluru | AC6: India | AD6: Karnataka | AE6: Beyond Bengaluru | AF6: India | AG6: Karnataka | AH6: Beyond Bengaluru | AI6: India | AJ6: Karnataka | AK6: Beyond Bengaluru | AL6: India | AM6: Karnataka | AN6: Beyond Bengaluru
C7: Consumer electronics: | E7: =D7*20% -> 0 | G7: =E7*5% -> 0 | I7: =E7-G7 -> 0 | M7: ESDM (Excluding cosumer electronics) | N7: =113-12 -> 101 | O7: =N7*20% -> 20.2 | P7: =O7*5% -> 1.01 | Q7: =148-14.5 -> 133.5 | R7: =Q7*20% -> 26.7 | S7: =R7*5% -> 1.335 | T7: =188.5-17 -> 171.5 | U7: =T7*20% -> 34.3 | V7: =U7*5% -> 1.715 | W7: =300-23 -> 277 | X7: =W7*20% -> 55.4 | Y7: =X7*5% -> 2.77 | Z7: =W7+12%*W7 -> 310.24 | AA7: =Z7*20% -> 62.048 | AB7: =AA7*5% -> 3.1024 | AC7: =Z7+12%*Z7 -> 347.4688 | AD7: =AC7*20% -> 69.49376 | AE7: =AD7*5% -> 3.474688 | AF7: =AC7+12%*AC7 -> 389.16506 | AG7: =AF7*20% -> 77.833011 | AH7: =AG7*5% -> 3.8916506 | AI7: =AF7+12%*AF7 -> 435.86486 | AJ7: =AI7*20% -> 87.172973 | AK7: =AJ7*5% -> 4.3586486 | AL7: =AI7+12%*AI7 -> 488.16865 | AM7: =AL7*20% -> 97.633729 | AN7: =AM7*5% -> 4.8816865
C8: Audio | D8: =2400/7500 -> 0.32 | E8: =D8*20% -> 0.064 | G8: =E8*5% -> 0.0032 | I8: =E8-G8 -> 0.0608 | M8: (Includes Major ESDM apart from other inclusions which are separate)
C9: Air Conditioners | D9: =11800/7500 -> 1.5733333 | E9: =D9*20% -> 0.31466667 | G9: =E9*5% -> 0.015733333 | I9: =E9-G9 -> 0.29893333
C10: Refrigerators | D10: =13500/7500 -> 1.8 | E10: =D10*20% -> 0.36 | G10: =E10*5% -> 0.018 | I10: =E10-G10 -> 0.342
C11: Televisions | D11: =7200/7500 -> 0.96 | E11: =D11*20% -> 0.192 | G11: =E11*5% -> 0.0096 | I11: =E11-G11 -> 0.1824
C12: Washing Machines | D12: =8900/7500 -> 1.1866667 | E12: =D12*20% -> 0.23733333 | G12: =E12*5% -> 0.011866667 | I12: =E12-G12 -> 0.22546667
C13: Semiconductor and Display Fab:
C14: Semicon Fab | E14: =D14*20% -> 0 | G14: =E14*5% -> 0 | I14: =E14-G14 -> 0
C15: Display Fab | E15: =D15*20% -> 0 | G15: =E15*5% -> 0 | I15: =E15-G15 -> 0
C16: Compound Semiconductors (Sic Power Electronics Market) | D16: ='Workings for ESDM'!F14 -> 0.041764504 | E16: =D16*20% -> 0.0083529008 | G16: =E16*5% -> 0.00041764504 | I16: =E16-G16 -> 0.0079352558
C17: Medtech (Medical Electronics) | D17: =4506.3/1000 -> 4.5063 | E17: =D17*20% -> 0.90126 | G17: =E17*5% -> 0.045063 | I17: =E17-G17 -> 0.856197
C18: Electric Vehicles components | D18: ='Workings for ESDM'!E32 -> 0.79793124 | E18: =D18*20% -> 0.15958625 | G18: =E18*5% -> 0.0079793124 | I18: =E18-G18 -> 0.15160694
C19: Total ESDM Revenue | D19: =SUM(D6:D17) -> 89.888065 | E19: =SUM(E6:E17) -> 17.977613 | F19: =SUM(F6:F17) -> 0 | G19: =SUM(G6:G17) -> 0.89888065 | H19: =SUM(H6:H17) -> 0 | I19: =SUM(I6:I17) -> 17.078732 | M19: Other Inclusions to ESDM: | S19: =R19*20% -> 0
M20: Consumer Electronics: | S20: =R20*20% -> 0
M21: Audio | N21: =3100/7500 -> 0.41333333 | O21: =N21*20% -> 0.082666667 | P21: =O21*5% -> 0.0041333333 | Q21: =3800/7500 -> 0.50666667 | R21: =Q21*20% -> 0.10133333 | S21: =R21*5% -> 0.0050666667 | T21: =4600/7500 -> 0.61333333 | U21: =T21*20% -> 0.12266667 | V21: =U21*5% -> 0.0061333333 | W21: =5700/7500 -> 0.76 | X21: =W21*20% -> 0.152 | Y21: =X21*5% -> 0.0076 | Z21: =W21+12%*W21 -> 0.8512 | AA21: =Z21*20% -> 0.17024 | AB21: =AA21*5% -> 0.008512 | AC21: =Z21+12%*Z21 -> 0.953344 | AD21: =AC21*20% -> 0.1906688 | AE21: =AD21*5% -> 0.00953344 | AF21: =AC21+12%*AC21 -> 1.0677453 | AG21: =AF21*20% -> 0.21354906 | AH21: =AG21*5% -> 0.010677453 | AI21: =AF21+12%*AF21 -> 1.1958747 | AJ21: =AI21*20% -> 0.23917494 | AK21: =AJ21*5% -> 0.011958747 | AL21: =AI21+12%*AI21 -> 1.3393797 | AM21: =AL21*20% -> 0.26787594 | AN21: =AM21*5% -> 0.013393797
